Workbook

Sheet Сводка
A1: Бизнес-центр, Навои — предварительные цены по этажам, сум
A2: Собрано 07.09.2026, ревизия 08.09.2026 (салон сверен с РП постранично, электрика переоценена, добавлены ориентиры на мебель/флорариумы/двери). Салон — по ведомости РП. Фитнес — свет/сантехника/отделка по РП, электрика — аналог салона. Офис и терраса — остекление по КП Imzo (вариант 2), тёплый пол, остальное — аналог салона по площади (оранжевое). Все «аналоги» заменить на данные РП.
A4: Раздел | B4: Салон (2 эт.) | C4: Фитнес (-1 эт.) | D4: Офис (3 эт.) | E4: Терраса | F4: ИТОГО
A5: Сантехника | B5: =SUMIF(Салон!$B$5:$B$200,$A5,Салон!$J$5:$J$200) -> 23100000 | C5: =SUMIF(Фитнес!$B$5:$B$60,$A5,Фитнес!$J$5:$J$60) -> 35500000 | D5: =SUMIF(Офис!$B$5:$B$60,$A5,Офис!$J$5:$J$60) -> 11400000 | E5: =SUMIF(Терраса!$B$5:$B$60,$A5,Терраса!$J$5:$J$60) -> 9300000 | F5: =SUM(B5:E5) -> 79300000
A6: Освещение | B6: =SUMIF(Салон!$B$5:$B$200,$A6,Салон!$J$5:$J$200) -> 28509150 | C6: =SUMIF(Фитнес!$B$5:$B$60,$A6,Фитнес!$J$5:$J$60) -> 28670000 | D6: =SUMIF(Офис!$B$5:$B$60,$A6,Офис!$J$5:$J$60) -> 18590000 | E6: =SUMIF(Терраса!$B$5:$B$60,$A6,Терраса!$J$5:$J$60) -> 20960000 | F6: =SUM(B6:E6) -> 96729150
A7: LED-подсветка | B7: =SUMIF(Салон!$B$5:$B$200,$A7,Салон!$J$5:$J$200) -> 30272800 | C7: =SUMIF(Фитнес!$B$5:$B$60,$A7,Фитнес!$J$5:$J$60) -> 0 | D7: =SUMIF(Офис!$B$5:$B$60,$A7,Офис!$J$5:$J$60) -> 20900000 | E7: =SUMIF(Терраса!$B$5:$B$60,$A7,Терраса!$J$5:$J$60) -> 23540000 | F7: =SUM(B7:E7) -> 74712800
A8: Электрика | B8: =SUMIF(Салон!$B$5:$B$200,$A8,Салон!$J$5:$J$200) -> 22210000 | C8: =SUMIF(Фитнес!$B$5:$B$60,$A8,Фитнес!$J$5:$J$60) -> 10465000 | D8: =SUMIF(Офис!$B$5:$B$60,$A8,Офис!$J$5:$J$60) -> 13635000 | E8: =SUMIF(Терраса!$B$5:$B$60,$A8,Терраса!$J$5:$J$60) -> 15700000 | F8: =SUM(B8:E8) -> 62010000
A9: Тёплый пол | B9: =SUMIF(Салон!$B$5:$B$200,$A9,Салон!$J$5:$J$200) -> 37301880 | C9: =SUMIF(Фитнес!$B$5:$B$60,$A9,Фитнес!$J$5:$J$60) -> 9919540 | D9: =SUMIF(Офис!$B$5:$B$60,$A9,Офис!$J$5:$J$60) -> 61050730 | E9: =SUMIF(Терраса!$B$5:$B$60,$A9,Терраса!$J$5:$J$60) -> 22003500 | F9: =SUM(B9:E9) -> 130275650
A10: Полы | B10: =SUMIF(Салон!$B$5:$B$200,$A10,Салон!$J$5:$J$200) -> 61225000 | C10: =SUMIF(Фитнес!$B$5:$B$60,$A10,Фитнес!$J$5:$J$60) -> 20671000 | D10: =SUMIF(Офис!$B$5:$B$60,$A10,Офис!$J$5:$J$60) -> 11956800 | E10: =SUMIF(Терраса!$B$5:$B$60,$A10,Терраса!$J$5:$J$60) -> 58065000 | F10: =SUM(B10:E10) -> 151917800
A11: Стены / потолок | B11: =SUMIF(Салон!$B$5:$B$200,$A11,Салон!$J$5:$J$200) -> 43286000 | C11: =SUMIF(Фитнес!$B$5:$B$60,$A11,Фитнес!$J$5:$J$60) -> 42365100 | D11: =SUMIF(Офис!$B$5:$B$60,$A11,Офис!$J$5:$J$60) -> 17125000 | E11: =SUMIF(Терраса!$B$5:$B$60,$A11,Терраса!$J$5:$J$60) -> 19344000 | F11: =SUM(B11:E11) -> 122120100
A12: Бамбуковые панели | B12: =SUMIF(Салон!$B$5:$B$200,$A12,Салон!$J$5:$J$200) -> 5040000 | C12: =SUMIF(Фитнес!$B$5:$B$60,$A12,Фитнес!$J$5:$J$60) -> 0 | D12: =SUMIF(Офис!$B$5:$B$60,$A12,Офис!$J$5:$J$60) -> 0 | E12: =SUMIF(Терраса!$B$5:$B$60,$A12,Терраса!$J$5:$J$60) -> 0 | F12: =SUM(B12:E12) -> 5040000
A13: Остекление | B13: =SUMIF(Салон!$B$5:$B$200,$A13,Салон!$J$5:$J$200) -> 5900000 | C13: =SUMIF(Фитнес!$B$5:$B$60,$A13,Фитнес!$J$5:$J$60) -> 0 | D13: =SUMIF(Офис!$B$5:$B$60,$A13,Офис!$J$5:$J$60) -> 40500000 | E13: =SUMIF(Терраса!$B$5:$B$60,$A13,Терраса!$J$5:$J$60) -> 284000000 | F13: =SUM(B13:E13) -> 330400000
A14: Мебель корпусная | B14: =SUMIF(Салон!$B$5:$B$200,$A14,Салон!$J$5:$J$200) -> 150570000 | C14: =SUMIF(Фитнес!$B$5:$B$60,$A14,Фитнес!$J$5:$J$60) -> 0 | D14: =SUMIF(Офис!$B$5:$B$60,$A14,Офис!$J$5:$J$60) -> 0 | E14: =SUMIF(Терраса!$B$5:$B$60,$A14,Терраса!$J$5:$J$60) -> 0 | F14: =SUM(B14:E14) -> 150570000
A15: Мебель мягкая | B15: =SUMIF(Салон!$B$5:$B$200,$A15,Салон!$J$5:$J$200) -> 0 | C15: =SUMIF(Фитнес!$B$5:$B$60,$A15,Фитнес!$J$5:$J$60) -> 0 | D15: =SUMIF(Офис!$B$5:$B$60,$A15,Офис!$J$5:$J$60) -> 0 | E15: =SUMIF(Терраса!$B$5:$B$60,$A15,Терраса!$J$5:$J$60) -> 0 | F15: =SUM(B15:E15) -> 0
A16: Мебель отдельно стоящая | B16: =SUMIF(Салон!$B$5:$B$200,$A16,Салон!$J$5:$J$200) -> 5400000 | C16: =SUMIF(Фитнес!$B$5:$B$60,$A16,Фитнес!$J$5:$J$60) -> 0 | D16: =SUMIF(Офис!$B$5:$B$60,$A16,Офис!$J$5:$J$60) -> 0 | E16: =SUMIF(Терраса!$B$5:$B$60,$A16,Терраса!$J$5:$J$60) -> 0 | F16: =SUM(B16:E16) -> 5400000
... A21: Двери | B21: =SUMIF(Салон!$B$5:$B$200,$A21,Салон!$J$5:$J$200) -> 55500000 | C21: =SUMIF(Фитнес!$B$5:$B$60,$A21,Фитнес!$J$5:$J$60) -> 0 | D21: =SUMIF(Офис!$B$5:$B$60,$A21,Офис!$J$5:$J$60) -> 0 | E21: =SUMIF(Терраса!$B$5:$B$60,$A21,Терраса!$J$5:$J$60) -> 0 | F21: =SUM(B21:E21) -> 55500000
A22: ИТОГО (известное) | B22: =SUM(B5:B21) -> 547154830 | C22: =SUM(C5:C21) -> 147590640 | D22: =SUM(D5:D21) -> 195157530 | E22: =SUM(E5:E21) -> 452912500 | F22: =SUM(F5:F21) -> 1342815500
A24: Полнота данных
B25: Салон | C25: Фитнес | D25: Офис | E25: Терраса
A26: Строк с «?» (кол-во неизвестно) | B26: =COUNTIF(Салон!$F$5:$F$112,"~?") -> 0 | C26: =COUNTIF(Фитнес!$F$5:$F$42,"~?") -> 0 | D26: =COUNTIF(Офис!$F$5:$F$36,"~?") -> 0 | E26: =COUNTIF(Терраса!$F$5:$F$33,"~?") -> 0
A27: Строк без цены | B27: =COUNTBLANK(Салон!$I$5:$I$112) -> 1 | C27: =COUNTBLANK(Фитнес!$I$5:$I$42) -> 2 | D27: =COUNTBLANK(Офис!$I$5:$I$36) -> 1 | E27: =COUNTBLANK(Терраса!$I$5:$I$33) -> 0
A28: Строк с предположенным кол-вом | B28: =COUNTIF(Салон!$K$5:$K$112,"предп.*") -> 8 | C28: =COUNTIF(Фитнес!$K$5:$K$42,"предп.*") -> 20 | D28: =COUNTIF(Офис!$K$5:$K$36,"предп.*") -> 27 | E28: =COUNTIF(Терраса!$K$5:$K$33,"предп.*") -> 26
A30: Как читать | B30: ИТОГО — только строки, где есть и количество, и цена. «?» и строки без цены в сумму не входят. Строки без цены остались только там, где цена принципиально не оценивается (ГКЛ-перегородки салона — по актам бригад; НП-1 фитнеса; покрытие офиса).
A31: Цены | B31: Один прайс на все этажи (лист «Прайс»). Поменял цену там — пересчиталось везде. Факт (магазин/КП) перекрывает ориентир.
A32: Уровень цен | B32: Ориентир — «средний–премиум» по рынку Узбекистана. Электрика с 08.09 — уровень AtlasDesign (чёрный), премиум-серии ×2. Мебель/флорариумы/декор/двери — оценки ±30 %, заменить на КП.
A33: Остекление | B33: Выбран вариант 2 Imzo: терраса 128 + офис 40,5 + фасад 156 = 324,5 млн. Фасад — по зданию, условно отнесён к террасе. Внутреннее остекление салона (5,9 м²) — предположение по развёрткам.
A34: Аналог салона | B34: Оранжевые строки на фитнесе/офисе/террасе — количества салона × (площадь этажа / 200 м²). Заглушка для порядка цифр, не спецификация. Внимание: электрика салона теперь без «столовых» 32→16 розеток и по новым ценам — аналоги пересчитались автоматически.

Sheet Прайс
A1: Единый прайс — цены за единицу, сум
A2: Синие ячейки — вводные. «Расчётная» = факт, если есть, иначе ориентир. Все этажи берут цену отсюда по коду. Ориентир — уровень «средний–премиум», оценка на 07.09.2026. 08.09.2026: электрика пересчитана на уровень AtlasDesign (чёрный); добавлены ориентиры на мебель, флорариумы, декор, ГКЛ-элементы, двери (группы МБ-, ФЛ-, ДЕК-, ГКЛ-, ДВ-, ОСТ-) — это оценки ±30 %, не КП.
A4: Код | B4: Группа | C4: Наименование | D4: Ед. | E4: Ориентир (средний–премиум) | F4: Факт (магазин / КП) | G4: Расчётная | H4: Источник / примечание
A5: СН-СМ-КУХ | B5: Сантехника | C5: Смеситель кухонный | D5: шт | E5: 1200000 | G5: =IF(ISNUMBER(F5),F5,E5) -> 1200000 | H5: оценка, уровень Lemark/Gappo/Frap-premium
A6: СН-СМ-НАКЛ | B6: Сантехника | C6: Смеситель для накладной раковины | D6: шт | E6: 900000 | G6: =IF(ISNUMBER(F6),F6,E6) -> 900000 | H6: оценка
A7: СН-СМ-ДУШ | B7: Сантехника | C7: Смеситель душевой / душевая стойка | D7: шт | E7: 1500000 | G7: =IF(ISNUMBER(F7),F7,E7) -> 1500000 | H7: оценка
A8: СН-РАК-КУХ-Б | B8: Сантехника | C8: Мойка кухонная 800×500 под столешницу | D8: шт | E8: 1500000 | G8: =IF(ISNUMBER(F8),F8,E8) -> 1500000 | H8: оценка
A9: СН-РАК-КУХ-М | B9: Сантехника | C9: Мойка кухонная 450×450 под столешницу | D9: шт | E9: 900000 | G9: =IF(ISNUMBER(F9),F9,E9) -> 900000 | H9: оценка
A10: СН-РАК-600 | B10: Сантехника | C10: Раковина накладная 600×400 | D10: шт | E10: 1300000 | G10: =IF(ISNUMBER(F10),F10,E10) -> 1300000 | H10: оценка
A11: СН-РАК-500 | B11: Сантехника | C11: Раковина накладная 500×450 | D11: шт | E11: 1100000 | G11: =IF(ISNUMBER(F11),F11,E11) -> 1100000 | H11: оценка
A12: СН-РАК-350 | B12: Сантехника | C12: Раковина встраиваемая 350×300 | D12: шт | E12: 800000 | G12: =IF(ISNUMBER(F12),F12,E12) -> 800000 | H12: оценка
A13: СН-ГИГДУШ | B13: Сантехника | C13: Гигиенический душ | D13: шт | E13: 900000 | G13: =IF(ISNUMBER(F13),F13,E13) -> 900000 | H13: оценка
A14: СН-УНИТ | B14: Сантехника | C14: Унитаз подвесной | D14: шт | E14: 2500000 | G14: =IF(ISNUMBER(F14),F14,E14) -> 2500000 | H14: оценка
A15: СН-ИНСТ | B15: Сантехника | C15: Инсталляция для унитаза | D15: шт | E15: 3000000 | G15: =IF(ISNUMBER(F15),F15,E15) -> 3000000 | H15: оценка (Geberit Duofix 3–4 млн, Alcaplast ~1,8 млн)
A16: СН-КНОП | B16: Сантехника | C16: Кнопка слива | D16: шт | E16: 700000 | G16: =IF(ISNUMBER(F16),F16,E16) -> 700000 | H16: оценка
... A20: СН-НАСОС | B20: Сантехника | C20: Канализационный насос (тип Sololift) | D20: шт | E20: 4500000 | G20: =IF(ISNUMBER(F20),F20,E20) -> 4500000 | H20: оценка, опция для подвала
A21: ОС-СПОТ-МАГ | B21: Освещение | C21: Спот магнитный поворотный 24 Вт | D21: шт | E21: 350000 | F21: 100000 | G21: =IF(ISNUMBER(F21),F21,E21) -> 100000 | H21: факт — прайс магазина 02.09.2026 (нижний тир, CRI проверить!)
A22: ОС-СПОТ-МАГ18 | B22: Освещение | C22: Спот магнитный 18 Вт | D22: шт | E22: 300000 | F22: 80000 | G22: =IF(ISNUMBER(F22),F22,E22) -> 80000 | H22: факт — прайс магазина
A23: ОС-РЕЛЬС-3 | B23: Освещение | C23: Рельс магнитный 3 м | D23: шт | E23: 750000 | F23: 250000 | G23: =IF(ISNUMBER(F23),F23,E23) -> 250000 | H23: факт — прайс магазина
A24: ОС-РЕЛЬС-2 | B24: Освещение | C24: Рельс магнитный 2 м | D24: шт | E24: 500000 | F24: 170000 | G24: =IF(ISNUMBER(F24),F24,E24) -> 170000 | H24: факт — прайс магазина
A25: ОС-РЕЛЬС-М | B25: Освещение | C25: Рельс магнитный, за 1 п.м. | D25: п.м. | E25: 250000 | F25: 85000 | G25: =IF(ISNUMBER(F25),F25,E25) -> 85000 | H25: факт — 250 000/3 м по прайсу магазина
A26: ОС-ТРОС | B26: Освещение | C26: Трос подвеса рельса | D26: шт | E26: 50000 | F26: 35000 | G26: =IF(ISNUMBER(F26),F26,E26) -> 35000 | H26: факт — прайс магазина
A27: ОС-БП-400 | B27: Освещение | C27: Блок питания 48V 400 Вт | D27: шт | E27: 300000 | F27: 200000 | G27: =IF(ISNUMBER(F27),F27,E27) -> 200000 | H27: факт — прайс магазина
A28: ОС-БП-200 | B28: Освещение | C28: Блок питания 48V 200 Вт | D28: шт | E28: 200000 | F28: 130000 | G28: =IF(ISNUMBER(F28),F28,E28) -> 130000 | H28: факт — прайс магазина
A29: ОС-БП-100 | B29: Освещение | C29: Блок питания 48V 100 Вт | D29: шт | E29: 150000 | F29: 100000 | G29: =IF(ISNUMBER(F29),F29,E29) -> 100000 | H29: факт — прайс магазина
A30: ОС-СОЕД | B30: Освещение | C30: Соединитель рельсов | D30: шт | E30: 40000 | F30: 25000 | G30: =IF(ISNUMBER(F30),F30,E30) -> 25000 | H30: факт — прайс магазина
A31: ОС-СОЕД-МЕТ | B31: Освещение | C31: Соединитель рельсов металлический | D31: шт | E31: 60000 | F31: 40000 | G31: =IF(ISNUMBER(F31),F31,E31) -> 40000 | H31: факт — прайс магазина
A32: ОС-ТОЧ | B32: Освещение | C32: Светильник накладной точечный 18 Вт | D32: шт | E32: 250000 | F32: 150000 | G32: =IF(ISNUMBER(F32),F32,E32) -> 150000 | H32: факт — прайс магазина
A33: ОС-БРА-90 | B33: Освещение | C33: Бра линейное 900 мм | D33: шт | E33: 500000 | F33: 300000 | G33: =IF(ISNUMBER(F33),F33,E33) -> 300000 | H33: факт — прайс магазина
A34: ОС-ПОДВ | B34: Освещение | C34: Подвесной светильник декоративный | D34: шт | E34: 600000 | G34: =IF(ISNUMBER(F34),F34,E34) -> 600000 | H34: оценка
A35: ОС-НАСТ | B35: Освещение | C35: Настенный светильник | D35: шт | E35: 450000 | G35: =IF(ISNUMBER(F35),F35,E35) -> 450000 | H35: оценка
A36: ОС-ЛДСП | B36: Освещение | C36: Подвесная конструкция ЛДСП с подсветкой 2000×1450 | D36: шт | E36: 3500000 | G36: =IF(ISNUMBER(F36),F36,E36) -> 3500000 | H36: оценка изготовления, уточнить у мебельщика
A37: LED-ПЛИНТ | B37: LED-подсветка | C37: Теневой плинтус с LED, за 1 п.м. | D37: п.м. | E37: 220000 | G37: =IF(ISNUMBER(F37),F37,E37) -> 220000 | H37: оценка (профиль + лента + рассеиватель)
A38: LED-ЛЕНТА | B38: LED-подсветка | C38: LED-лента 24V в профиле, за 1 п.м. | D38: п.м. | E38: 90000 | G38: =IF(ISNUMBER(F38),F38,E38) -> 90000 | H38: оценка
A39: LED-БП | B39: LED-подсветка | C39: Блок питания / драйвер LED | D39: шт | E39: 250000 | G39: =IF(ISNUMBER(F39),F39,E39) -> 250000 | H39: оценка
A40: ЭЛ-ВЫК1 | B40: Электрика | C40: Выключатель 1-кл (чёрный) | D40: шт | E40: 55000 | G40: =IF(ISNUMBER(F40),F40,E40) -> 55000 | H40: ориентир по Systeme/Schneider AtlasDesign «карбон»; ikarvon.uz 08.09.2026: розетка с/з алюминий 44 200. Премиум (Legrand Inspiria / Unica) — ×2
A41: ЭЛ-ВЫК2 | B41: Электрика | C41: Выключатель 2-кл (чёрный) | D41: шт | E41: 80000 | G41: =IF(ISNUMBER(F41),F41,E41) -> 80000 | H41: ориентир AtlasDesign «карбон»; премиум ×2
A42: ЭЛ-РОЗ | B42: Электрика | C42: Розетка с заземлением (чёрная) | D42: шт | E42: 65000 | G42: =IF(ISNUMBER(F42),F42,E42) -> 65000 | H42: ориентир AtlasDesign «карбон» (механизм); ikarvon.uz 08.09.2026: алюминий 44 200. Премиум ×2
A43: ЭЛ-РАМ1 | B43: Электрика | C43: Рамка 1-пост | D43: шт | E43: 25000 | G43: =IF(ISNUMBER(F43),F43,E43) -> 25000 | H43: ориентир AtlasDesign; премиум ×2
A44: ЭЛ-РАМ2 | B44: Электрика | C44: Рамка 2-пост | D44: шт | E44: 45000 | G44: =IF(ISNUMBER(F44),F44,E44) -> 45000 | H44: ориентир AtlasDesign; премиум ×2
...

Sheet Салон
A1: Салон — 2 этаж (200 м², РП INSIDROOM, 41 л.)
A2: Кол-во и «Цена ручн.» — синие вводные. Цена берётся из листа «Прайс» по коду, ручная цена перекрывает прайс. Жёлтые «?» — данных нет, сумма по строке = 0 до заполнения. Оранжевые — количество предположено, проверить по РП. Ревизия 08.09.2026: сверено с РП INSIDROOM (40 л.) — исправлены столы М11 (1→6), розетки в столах (32→16), поддоны (1→2), рейки (27→54), размеры/привязки флорариумов, барельеф (пом. 5), добавлены подиумы, фрески, внутреннее остекление, запас кафеля, ориентиры на мебель/флорариумы/двери. Список — лист «Проверка РП салона». 09.09.2026: корректировки заказчика — столы 4, стеллажи 2, двери 7 + 3 стеклянные; зелёные строки — уже куплено (цена = 0). Список закупок заказчика 09.09 внесён: «закуп заказчика» — зелёное, цена 0; «заказ» — изготовление, остаётся в сумме.
A4: № | B4: Раздел | C4: Наименование | D4: Характеристика | E4: Ед. | F4: Кол-во | G4: Код прайса | H4: Цена ручн. | I4: Цена | J4: Сумма | K4: Откуда кол-во | L4: Примечание
A5: 1 | B5: Мебель корпусная | C5: Стойка ресепшен | D5: В900 × Д3660 × Г820 | E5: шт | F5: 1 | G5: МБ-СТОЙКА | I5: =IF(ISNUMBER(H5),H5,IF(G5<>"",IFERROR(INDEX(Прайс!$G$5:$G$150,MATCH(G5,Прайс!$A$5:$A$150,0)),""),"")) -> 20000000 | J5: =IF(AND(ISNUMBER(F5),ISNUMBER(I5)),F5*I5,"") -> 20000000 | K5: по РП | L5: пом. 1 Ресепшен; цена — ориентир прайса (±30 %), заменить на КП мебельщика
A6: 2 | B6: Мебель корпусная | C6: Шкаф в ресепшен | D6: В2530 × Д1400 × Г600 (1,4 п.м.) | E6: п.м. | F6: 1.4 | G6: МБ-ШКАФ-ПМ | I6: =IF(ISNUMBER(H6),H6,IF(G6<>"",IFERROR(INDEX(Прайс!$G$5:$G$150,MATCH(G6,Прайс!$A$5:$A$150,0)),""),"")) -> 3500000 | J6: =IF(AND(ISNUMBER(F6),ISNUMBER(I6)),F6*I6,"") -> 4900000 | K6: по РП | L6: пом. 1; у заказчика «стеллаж-витрина для лаков возле администратора» — заказ; вероятно, это он
A7: 3 | B7: Мебель корпусная | C7: Шкаф в хранилище | D7: В2400 × Д1770 × Г700 (1,77 п.м.) | E7: п.м. | F7: 1.77 | G7: МБ-ШКАФ-ПМ | I7: =IF(ISNUMBER(H7),H7,IF(G7<>"",IFERROR(INDEX(Прайс!$G$5:$G$150,MATCH(G7,Прайс!$A$5:$A$150,0)),""),"")) -> 3500000 | J7: =IF(AND(ISNUMBER(F7),ISNUMBER(I7)),F7*I7,"") -> 6195000 | K7: по РП | L7: пом. 10 Склад; у заказчика «полки витражные под ключ для материалов — рассчитать» (заказ)
A8: 4 | B8: Мебель корпусная | C8: Шкаф в комнате для курения | D8: В2400 × Д400 × Г320 (0,4 п.м.) | E8: п.м. | F8: 0.4 | G8: МБ-ШКАФ-ПМ | I8: =IF(ISNUMBER(H8),H8,IF(G8<>"",IFERROR(INDEX(Прайс!$G$5:$G$150,MATCH(G8,Прайс!$A$5:$A$150,0)),""),"")) -> 3500000 | J8: =IF(AND(ISNUMBER(F8),ISNUMBER(I8)),F8*I8,"") -> 1400000 | K8: по РП | L8: пом. 9; в списке заказчика для курилки только урна/столик/диван — шкаф нужен?
A9: 5 | B9: Мебель корпусная | C9: Открытая полка в кабинете топ-мастера 1 | D9: В2400 × Д3150 × Г350 (3,15 п.м.) | E9: п.м. | F9: 3.15 | G9: МБ-ПОЛКА-ПМ | H9: 0 | I9: =IF(ISNUMBER(H9),H9,IF(G9<>"",IFERROR(INDEX(Прайс!$G$5:$G$150,MATCH(G9,Прайс!$A$5:$A$150,0)),""),"")) -> 0 | J9: =IF(AND(ISNUMBER(F9),ISNUMBER(I9)),F9*I9,"") -> 0 | K9: закуп заказчика | L9: список заказчика: стеллаж 2м×40×80 в кабинете — закуп («дафна»); в РП была открытая полка 3150; в сумму не входит
A10: 6 | B10: Мебель корпусная | C10: Кухонный гарнитур в кабинете топ-мастера 1 | D10: В900 × Д2000 × Г600 (2,0 п.м.) | E10: п.м. | F10: 2 | G10: МБ-КУХ-ПМ | I10: =IF(ISNUMBER(H10),H10,IF(G10<>"",IFERROR(INDEX(Прайс!$G$5:$G$150,MATCH(G10,Прайс!$A$5:$A$150,0)),""),"")) -> 4500000 | J10: =IF(AND(ISNUMBER(F10),ISNUMBER(I10)),F10*I10,"") -> 9000000 | K10: по РП | L10: пом. 4; в списке заказчика в кабинете только раковина (закуп) — под неё нужна тумба, гарнитур 2000 не упомянут
A11: 7 | B11: Мебель корпусная | C11: Шкаф в кабинете топ-мастера | D11: В2400 × Д1500 × Г600 (1,5 п.м.) | E11: п.м. | F11: 1.5 | G11: МБ-ШКАФ-ПМ | I11: =IF(ISNUMBER(H11),H11,IF(G11<>"",IFERROR(INDEX(Прайс!$G$5:$G$150,MATCH(G11,Прайс!$A$5:$A$150,0)),""),"")) -> 3500000 | J11: =IF(AND(ISNUMBER(F11),ISNUMBER(I11)),F11*I11,"") -> 5250000 | K11: по РП | L11: пом. 4; в списке заказчика нет — вместо него стеллаж 2 м (закуп) и комод под ключ (заказ)
A12: 8 | B12: Мебель корпусная | C12: Шкаф над инсталляцией | D12: В1760 × Д3150 × Г350 (3,15 п.м.) | E12: п.м. | F12: 3.15 | G12: МБ-ШКАФ-ПМ | I12: =IF(ISNUMBER(H12),H12,IF(G12<>"",IFERROR(INDEX(Прайс!$G$5:$G$150,MATCH(G12,Прайс!$A$5:$A$150,0)),""),"")) -> 3500000 | J12: =IF(AND(ISNUMBER(F12),ISNUMBER(I12)),F12*I12,"") -> 11025000 | K12: по РП | L12: пом. 8; в списке заказчика только зеркало с подсветкой (заказ) — шкаф над инсталляцией не упомянут
A13: 9 | B13: Мебель корпусная | C13: Тумба под раковиной | D13: В400 × Д1240 × Г500 | E13: шт | F13: 1 | G13: МБ-ТУМБА | I13: =IF(ISNUMBER(H13),H13,IF(G13<>"",IFERROR(INDEX(Прайс!$G$5:$G$150,MATCH(G13,Прайс!$A$5:$A$150,0)),""),"")) -> 3000000 | J13: =IF(AND(ISNUMBER(F13),ISNUMBER(I13)),F13*I13,"") -> 3000000 | K13: по РП | L13: пом. 8 С/У; цена — ориентир прайса (±30 %), заменить на КП мебельщика
A14: 10 | B14: Мебель корпусная | C14: Кухонный гарнитур в комнате стерилизации | D14: В900 × Д2410 × Г2200 угловой (2,41 + 2,2 ≈ 4,6 п.м.) | E14: п.м. | F14: 4.6 | G14: МБ-КУХ-ПМ | I14: =IF(ISNUMBER(H14),H14,IF(G14<>"",IFERROR(INDEX(Прайс!$G$5:$G$150,MATCH(G14,Прайс!$A$5:$A$150,0)),""),"")) -> 4500000 | J14: =IF(AND(ISNUMBER(F14),ISNUMBER(I14)),F14*I14,"") -> 20700000 | K14: по РП | L14: пом. 7; у заказчика: комод 1 + тумба для стерилизаторов 1 — заказ; раковина — закуп
A15: 11 | B15: Мебель корпусная | C15: Маникюрный стол 2200 со встроенным пылесосом (зал) | D15: В750 × Д2200 × Г600 | E15: шт | F15: 4 | G15: МБ-СТОЛ-МАН | I15: =IF(ISNUMBER(H15),H15,IF(G15<>"",IFERROR(INDEX(Прайс!$G$5:$G$150,MATCH(G15,Прайс!$A$5:$A$150,0)),""),"")) -> 5000000 | J15: =IF(AND(ISNUMBER(F15),ISNUMBER(I15)),F15*I15,"") -> 20000000 | K15: по заказчику (заказ) | L15: пом. 2; список заказчика: 4 стола со встр. пылесосом — заказ (изготовление). Кабинеты — отдельной строкой ниже
A16: 12 | B16: Мебель корпусная | C16: Стеллаж | D16: В2400 × Д900 × Г300, 2 шт (1,8 п.м.) | E16: п.м. | F16: 1.8 | G16: МБ-ПОЛКА-ПМ | I16: =IF(ISNUMBER(H16),H16,IF(G16<>"",IFERROR(INDEX(Прайс!$G$5:$G$150,MATCH(G16,Прайс!$A$5:$A$150,0)),""),"")) -> 2500000 | J16: =IF(AND(ISNUMBER(F16),ISNUMBER(I16)),F16*I16,"") -> 4500000 | K16: по заказчику 09.09 | L16: пом. 10 Склад; заказчик — 2 шт (в РП 1)
A17: 13 | B17: Мебель корпусная | C17: Шкафчики для персонала 300×2000×500 — 10 шт (вместо шкафа М13) | D17: 10 × 300 = 3,0 п.м., h=2000 | E17: п.м. | F17: 3 | G17: МБ-ШКАФ-ПМ | I17: =IF(ISNUMBER(H17),H17,IF(G17<>"",IFERROR(INDEX(Прайс!$G$5:$G$150,MATCH(G17,Прайс!$A$5:$A$150,0)),""),"")) -> 3500000 | J17: =IF(AND(ISNUMBER(F17),ISNUMBER(I17)),F17*I17,"") -> 10500000 | K17: по заказчику (заказ) | L17: пом. 6; в РП шкаф 3660; у заказчика 10 локеров 300×2000×500 — заказ
A18: 14 | B18: Мебель корпусная | C18: Обеденный стол в кухне | D18: В900 × Д3140 × Г600 | E18: шт | F18: 1 | G18: МБ-СТОЛ-ОБЕД | H18: 0 | I18: =IF(ISNUMBER(H18),H18,IF(G18<>"",IFERROR(INDEX(Прайс!$G$5:$G$150,MATCH(G18,Прайс!$A$5:$A$150,0)),""),"")) -> 0 | J18: =IF(AND(ISNUMBER(F18),ISNUMBER(I18)),F18*I18,"") -> 0 | K18: куплено | L18: 08.09 сказано «куплен», в списке 09.09 — стол обеденный 1800×1000×750 «заказ». Противоречие — уточнить. В РП 3140×600. Пока цена 0
A19: 15 | B19: Мебель корпусная | C19: Шкаф в кабинете топ-мастера 2 | D19: В2400 × Д1800 × Г600 (1,8 п.м.) | E19: п.м. | F19: 1.8 | G19: МБ-ШКАФ-ПМ | I19: =IF(ISNUMBER(H19),H19,IF(G19<>"",IFERROR(INDEX(Прайс!$G$5:$G$150,MATCH(G19,Прайс!$A$5:$A$150,0)),""),"")) -> 3500000 | J19: =IF(AND(ISNUMBER(F19),ISNUMBER(I19)),F19*I19,"") -> 6300000 | K19: по РП | L19: пом. 5 ВИП; у заказчика «стеллаж/полки» — заказ
A20: 16 | B20: Мебель мягкая | C20: Диван | D20: В400 (спинка 650) × Д2600 × Г1000, спинка 250 | E20: шт | F20: 1 | G20: МБ-ДИВАН | H20: 0 | I20: =IF(ISNUMBER(H20),H20,IF(G20<>"",IFERROR(INDEX(Прайс!$G$5:$G$150,MATCH(G20,Прайс!$A$5:$A$150,0)),""),"")) -> 0 | J20: =IF(AND(ISNUMBER(F20),ISNUMBER(I20)),F20*I20,"") -> 0 | K20: закуп заказчика | L20: список заказчика: диван 2 м в маникюрном зале — закуп; в сумму не входит
A21: 17 | B21: Мебель мягкая | C21: Диван (дизайнерский, розовый) | D21: размеры в РП не указаны | E21: шт | F21: 1 | G21: МБ-ДИВАН-ДИЗ | H21: 0 | I21: =IF(ISNUMBER(H21),H21,IF(G21<>"",IFERROR(INDEX(Прайс!$G$5:$G$150,MATCH(G21,Прайс!$A$5:$A$150,0)),""),"")) -> 0 | J21: =IF(AND(ISNUMBER(F21),ISNUMBER(I21)),F21*I21,"") -> 0 | K21: закуп заказчика | L21: в списке заказчика второй диван — только в курилке (закуп); розовый дизайнерский из РП, видимо, это он — уточнить; в сумму не входит
A22: 18 | B22: Мебель отдельно стоящая | C22: Кухонный стул | D22: размеры не указаны | E22: шт | F22: 4 | G22: МБ-СТУЛ-КУХ | H22: 0 | I22: =IF(ISNUMBER(H22),H22,IF(G22<>"",IFERROR(INDEX(Прайс!$G$5:$G$150,MATCH(G22,Прайс!$A$5:$A$150,0)),""),"")) -> 0 | J22: =IF(AND(ISNUMBER(F22),ISNUMBER(I22)),F22*I22,"") -> 0 | K22: закуп заказчика | L22: список заказчика: стулья в персоналку 4 — закуп; в сумму не входит
A23: 19 | B23: Мебель отдельно стоящая | C23: Журнальный стол | D23: В500, R300 | E23: шт | F23: 1 | G23: МБ-ЖУРН | H23: 0 | I23: =IF(ISNUMBER(H23),H23,IF(G23<>"",IFERROR(INDEX(Прайс!$G$5:$G$150,MATCH(G23,Прайс!$A$5:$A$150,0)),""),"")) -> 0 | J23: =IF(AND(ISNUMBER(F23),ISNUMBER(I23)),F23*I23,"") -> 0 | K23: закуп заказчика | L23: список заказчика: столик кофейный (зал) 1 + столик в курилке 1 — закуп; в сумму не входит
A24: 20 | B24: Мебель отдельно стоящая | C24: Журнальный стол | D24: В400, R600 | E24: шт | F24: 1 | G24: МБ-ЖУРН | H24: 0 | I24: =IF(ISNUMBER(H24),H24,IF(G24<>"",IFERROR(INDEX(Прайс!$G$5:$G$150,MATCH(G24,Прайс!$A$5:$A$150,0)),""),"")) -> 0 | J24: =IF(AND(ISNUMBER(F24),ISNUMBER(I24)),F24*I24,"") -> 0 | K24: закуп заказчика | L24: список заказчика: столик кофейный (зал) 1 + столик в курилке 1 — закуп; в сумму не входит
A25: 21 | B25: Мебель отдельно стоящая | C25: Кресло в ресепшен | D25: В1200 × 650 × 650 | E25: шт | F25: 2 | G25: МБ-КРЕСЛО-РЕЦ | H25: 0 | I25: =IF(ISNUMBER(H25),H25,IF(G25<>"",IFERROR(INDEX(Прайс!$G$5:$G$150,MATCH(G25,Прайс!$A$5:$A$150,0)),""),"")) -> 0 | J25: =IF(AND(ISNUMBER(F25),ISNUMBER(I25)),F25*I25,"") -> 0 | K25: закуп заказчика | L25: список заказчика: стулья на ресепшен для админа 2 — закуп; в сумму не входит
A26: 22 | B26: Мебель отдельно стоящая | C26: Маникюрный стул | D26: В900 × 450 × 450 | E26: шт | F26: 18 | G26: МБ-СТУЛ-МАСТ | H26: 0 | I26: =IF(ISNUMBER(H26),H26,IF(G26<>"",IFERROR(INDEX(Прайс!$G$5:$G$150,MATCH(G26,Прайс!$A$5:$A$150,0)),""),"")) -> 0 | J26: =IF(AND(ISNUMBER(F26),ISNUMBER(I26)),F26*I26,"") -> 0 | K26: закуп заказчика | L26: список заказчика: стулья мастеров 8 (зал) + 6 (педикюр) + 2 + 2 (кабинеты) = 18, Китай, куплены; в сумму не входит
A27: 23 | B27: Мебель отдельно стоящая | C27: Маникюрное кресло | D27: В900 × 650 × 650 | E27: шт | F27: 10 | G27: МБ-КРЕСЛО-КЛ | H27: 0 | I27: =IF(ISNUMBER(H27),H27,IF(G27<>"",IFERROR(INDEX(Прайс!$G$5:$G$150,MATCH(G27,Прайс!$A$5:$A$150,0)),""),"")) -> 0 | J27: =IF(AND(ISNUMBER(F27),ISNUMBER(I27)),F27*I27,"") -> 0 | K27: закуп заказчика | L27: список заказчика: стулья для клиентов 8 (зал) + 1 + 1 (кабинеты) = 10 — закуп. 08.09 было сказано «считаем» — по списку это закуп заказчика, уточнить; в сумму не входит
A28: 24 | B28: Мебель отдельно стоящая | C28: Пуфик | D28: В500 × 450 × 450 | E28: шт | F28: 3 | G28: МБ-ПУФ | I28: =IF(ISNUMBER(H28),H28,IF(G28<>"",IFERROR(INDEX(Прайс!$G$5:$G$150,MATCH(G28,Прайс!$A$5:$A$150,0)),""),"")) -> 1800000 | J28: =IF(AND(ISNUMBER(F28),ISNUMBER(I28)),F28*I28,"") -> 5400000 | K28: по РП | L28: пом. 1; в списке заказчика пуфов нет — нужны ли?
A29: 25 | B29: Мебель отдельно стоящая | C29: Кресло в кабинете топ-мастера (педикюрное, Китай) | D29: В1000 × 1000 × 1500 | E29: шт | F29: 2 | G29: МБ-КРЕСЛО-ТОП | H29: 0 | I29: =IF(ISNUMBER(H29),H29,IF(G29<>"",IFERROR(INDEX(Прайс!$G$5:$G$150,MATCH(G29,Прайс!$A$5:$A$150,0)),""),"")) -> 0 | J29: =IF(AND(ISNUMBER(F29),ISNUMBER(I29)),F29*I29,"") -> 0 | K29: закуп заказчика | L29: список заказчика: в каждом кабинете педикюрное кресло (Китай, куплено) — это и есть «кресло топ-мастера»; в сумму не входит
A30: 26 | B30: Мебель отдельно стоящая | C30: Педикюрное кресло | D30: В1000 × 1000 × 1800 | E30: шт | F30: 3 | G30: МБ-КРЕСЛО-ПЕД | H30: 0 | I30: =IF(ISNUMBER(H30),H30,IF(G30<>"",IFERROR(INDEX(Прайс!$G$5:$G$150,MATCH(G30,Прайс!$A$5:$A$150,0)),""),"")) -> 0 | J30: =IF(AND(ISNUMBER(F30),ISNUMBER(I30)),F30*I30,"") -> 0 | K30: куплено | L30: куплены заказчиком (3 шт) — остаются только подиумы ГКЛ; в сумму не входит (цена ручн. = 0)
A31: 27 | B31: Сантехника | C31: Кухонный смеситель | D31: выводы ГВС+ХВС h=600, слив h=500 | E31: шт | F31: 2 | G31: СН-СМ-КУХ | I31: =IF(ISNUMBER(H31),H31,IF(G31<>"",IFERROR(INDEX(Прайс!$G$5:$G$150,MATCH(G31,Прайс!$A$5:$A$150,0)),""),"")) -> 1200000 | J31: =IF(AND(ISNUMBER(F31),ISNUMBER(I31)),F31*I31,"") -> 2400000 | K31: по РП | L31: пом. 6, 7
A32: 28 | B32: Сантехника | C32: Накладной смеситель 1 | D32: ГВС+ХВС и слив в ГКЛ-коробе | E32: шт | F32: 4 | G32: СН-СМ-НАКЛ | I32: =IF(ISNUMBER(H32),H32,IF(G32<>"",IFERROR(INDEX(Прайс!$G$5:$G$150,MATCH(G32,Прайс!$A$5:$A$150,0)),""),"")) -> 900000 | J32: =IF(AND(ISNUMBER(F32),ISNUMBER(I32)),F32*I32,"") -> 3600000 | K32: по РП | L32: пом. 3, 4, 5
A33: 29 | B33: Сантехника | C33: Накладной смеситель 2 | D33: ГВС+ХВС h=600, слив h=500 | E33: шт | F33: 4 | G33: СН-СМ-НАКЛ | I33: =IF(ISNUMBER(H33),H33,IF(G33<>"",IFERROR(INDEX(Прайс!$G$5:$G$150,MATCH(G33,Прайс!$A$5:$A$150,0)),""),"")) -> 900000 | J33: =IF(AND(ISNUMBER(F33),ISNUMBER(I33)),F33*I33,"") -> 3600000 | K33: по РП | L33: пом. 3, 5, 8
A34: 30 | B34: Сантехника | C34: Накладной смеситель 3 | D34: ГВС+ХВС и слив в ГКЛ-коробе | E34: шт | F34: 2 | G34: СН-СМ-НАКЛ | I34: =IF(ISNUMBER(H34),H34,IF(G34<>"",IFERROR(INDEX(Прайс!$G$5:$G$150,MATCH(G34,Прайс!$A$5:$A$150,0)),""),"")) -> 900000 | J34: =IF(AND(ISNUMBER(F34),ISNUMBER(I34)),F34*I34,"") -> 1800000 | K34: по РП | L34: пом. 4, 5
A35: 31 | B35: Сантехника | C35: Кухонная раковина 800×500 | D35: монтаж под столешницу | E35: шт | F35: 1 | G35: СН-РАК-КУХ-Б | H35: 0 | I35: =IF(ISNUMBER(H35),H35,IF(G35<>"",IFERROR(INDEX(Прайс!$G$5:$G$150,MATCH(G35,Прайс!$A$5:$A$150,0)),""),"")) -> 0 | J35: =IF(AND(ISNUMBER(F35),ISNUMBER(I35)),F35*I35,"") -> 0 | K35: закуп заказчика | L35: пом. 7 Стерилизация — раковина в списке заказчика «закуп»; в сумму не входит
A36: 32 | B36: Сантехника | C36: Кухонная раковина 450×450 | D36: монтаж под столешницу | E36: шт | F36: 1 | G36: СН-РАК-КУХ-М | H36: 0 | I36: =IF(ISNUMBER(H36),H36,IF(G36<>"",IFERROR(INDEX(Прайс!$G$5:$G$150,MATCH(G36,Прайс!$A$5:$A$150,0)),""),"")) -> 0 | J36: =IF(AND(ISNUMBER(F36),ISNUMBER(I36)),F36*I36,"") -> 0 | K36: закуп заказчика | L36: пом. 6 Персоналка — раковина «закуп»; в сумму не входит
A37: 33 | B37: Сантехника | C37: Накладная раковина в С/У 600×400 | E37: шт | F37: 1 | G37: СН-РАК-600 | I37: =IF(ISNUMBER(H37),H37,IF(G37<>"",IFERROR(INDEX(Прайс!$G$5:$G$150,MATCH(G37,Прайс!$A$5:$A$150,0)),""),"")) -> 1300000 | J37: =IF(AND(ISNUMBER(F37),ISNUMBER(I37)),F37*I37,"") -> 1300000 | K37: по РП | L37: пом. 8 С/У
A38: 34 | B38: Сантехника | C38: Накладная раковина в педикюрной зоне 500×450 | E38: шт | F38: 3 | G38: СН-РАК-500 | I38: =IF(ISNUMBER(H38),H38,IF(G38<>"",IFERROR(INDEX(Прайс!$G$5:$G$150,MATCH(G38,Прайс!$A$5:$A$150,0)),""),"")) -> 1100000 | J38: =IF(AND(ISNUMBER(F38),ISNUMBER(I38)),F38*I38,"") -> 3300000 | K38: по РП | L38: пом. 3 Педикюрная
A39: 35 | B39: Сантехника | C39: Раковина, встроенная в ГКЛ-короб 350×300 | D39: в кабинетах топ-мастеров | E39: шт | F39: 2 | G39: СН-РАК-350 | H39: 0 | I39: =IF(ISNUMBER(H39),H39,IF(G39<>"",IFERROR(INDEX(Прайс!$G$5:$G$150,MATCH(G39,Прайс!$A$5:$A$150,0)),""),"")) -> 0 | J39: =IF(AND(ISNUMBER(F39),ISNUMBER(I39)),F39*I39,"") -> 0 | K39: закуп заказчика | L39: пом. 4, 5 — раковины в кабинетах «закуп»; в сумму не входит
A40: 36 | B40: Сантехника | C40: Гигиенический душ | D40: выводы ГВС+ХВС h=700 | E40: шт | F40: 1 | G40: СН-ГИГДУШ | I40: =IF(ISNUMBER(H40),H40,IF(G40<>"",IFERROR(INDEX(Прайс!$G$5:$G$150,MATCH(G40,Прайс!$A$5:$A$150,0)),""),"")) -> 900000 | J40: =IF(AND(ISNUMBER(F40),ISNUMBER(I40)),F40*I40,"") -> 900000 | K40: по РП | L40: пом. 8 С/У
A41: 37 | B41: Сантехника | C41: Подвесной унитаз | E41: шт | F41: 1 | G41: СН-УНИТ | I41: =IF(ISNUMBER(H41),H41,IF(G41<>"",IFERROR(INDEX(Прайс!$G$5:$G$150,MATCH(G41,Прайс!$A$5:$A$150,0)),""),"")) -> 2500000 | J41: =IF(AND(ISNUMBER(F41),ISNUMBER(I41)),F41*I41,"") -> 2500000 | K41: по РП | L41: пом. 8 С/У
...

Sheet Проверка РП салона
A1: Салон, 2 этаж — сверка таблицы с РП INSIDROOM (40 листов), 08.09.2026
A2: Что проверялось: каждая спецификация РП против строк листа «Салон». Статус: ✔ совпадает · ✎ исправлено в файле · ⚠ ошибка/нестыковка в самом РП — вопрос дизайнеру
A4: № | B4: Лист РП | C4: Раздел | D4: Что в РП | E4: Что было в таблице | F4: Статус | G4: Что сделано / вопрос | H4: Влияние на сумму, сум
A5: 1 | B5: л.3–4 | C5: Мебель | D5: 15 позиций корпусной, 2 мягкой, 9 отдельно стоящей; М11 маникюрный стол — 1 шт | E5: то же, без цен | F5: ⚠ ✎ | G5: На плане л.2 стол М11 стоит 6 раз (4 в зоне 2 + по 1 у топ-мастеров); 10 кресел клиента М8 = 4×2 + 2 → принято 6. Всем позициям присвоены ориентиры прайса (МБ-…) | H5: +≈30 млн (5 столов)
A6: 2 | B6: л.3 | C6: Мебель | D6: Марки М2 (шкаф) и М2 (диван), М3, М4, М6–М11 дублируются между корпусной и отдельно стоящей | E6: отмечено | F6: ⚠ | G6: При заказе указывать группу — иначе мебельщик соберёт не то | H6: —
A7: 3 | B7: л.7 | C7: Сантехника | D7: Смесители 2+4+4+2 = 12; раковины 1+1+1+3+2 = 8; гиг. душ, унитаз, инсталляция, кнопка | E7: совпадает | F7: ✔ ⚠ | G7: Количества совпадают, но 4 «накладных смесителя 2» не имеют раковин в спецификации — вопрос дизайнеру | H7: возможно +4 раковины ≈ 4–5 млн
A8: 4 | B8: л.8 | C8: Освещение | D8: 101 спот, шинопровод 9800/5000×2/4800×4/3100×4/2850×3/2440/1800×2 = 66 п.м., курилка 2+1 | E8: совпадает | F8: ✔ | G8: Подвесная конструкция: л.9 — ЛДСП, л.8/л.11 — МДФ; 2 шт по плану (пом. 4 и 5) | H8: —
A9: 5 | B9: л.6 | C9: LED | D9: Теневой плинтус 102 п.м. | E9: совпадает | F9: ✔ | G9: Метраж LED-лент в РП не посчитан — оставлены снятые с л.10 54 / 8 / 13,92 п.м. | H9: —
A10: 6 | B10: л.13 | C10: Электрика | D10: 1-кл 8, 2-кл 30, розетки 105, рамки 10/11/8/12/4; примечание: внутрипольные блоки не входят | E10: совпадает; + в столах 32/8/4, блоки 2 | F10: ✎ ⚠ | G10: Метка «8 розеток в столе!» стоит на РЯД из 2 столов → 16, а не 32. Нестыковка РП: 143 механизма против 124 постов в рамках. Цены электрики переведены на уровень AtlasDesign (чёрный) | H10: −≈2,4 млн (розетки), −≈19 млн (цены)
A11: 7 | B11: л.15 | C11: Полы | D11: Кафель 1200×1200 — 140 шт «с запасом +10 %» | E11: 140 шт | F11: ⚠ ✎ | G11: 140 × 1,44 = 201,6 м² = площадь 200 м² без запаса. Добавлена строка «запас 15 шт» | H11: +5,9 млн
A12: 8 | B12: л.21 | C12: Стены | D12: Краска потолок 290 м², стены 350 м² (+15 %) | E12: совпадает | F12: ✔ | G12: Остаётся расхождение 18,45 млн (по м²) против 12 млн (16 банок) — свести; л.21 упоминает штукатурку | H12: —
A13: 9 | B13: л.16 | C13: Бамбук | D13: Панели 3 + 9, профили 8/2/14 | E13: совпадает | F13: ✔ | G13: — | H13: —
A14: 10 | B14: л.17–20 | C14: Флорариумы | D14: Ф1 1040×2540; Ф2 1240×2140+стекло; Ф3 1100×2540; Ф4 600×2560; Ф5 1100×2540; Ф6 600×2540 | E14: Ф3 1100×2560, Ф4 1100×2540, Ф6 1100×2540; Ф1 — «пом. 4» | F14: ✎ ⚠ | G14: Размеры Ф3/Ф4/Ф6 исправлены, привязки — по л.17 (Ф1, Ф2 — в С/У). Ф5/Ф6 перепутаны между л.20 и развёртками л.28. Единица → м² (13,9 м² всего), ориентир 4 млн/м² | H14: +≈56 млн
A15: 11 | B15: л.22 | C15: Декор | D15: Барельеф из гипса 3080×2540 | E15: 1 шт, «пом. 3» | F15: ✎ | G15: Стоит в пом. 5 стена A (л.31). Переведён в м² (7,82), ориентир 1,8 млн/м² | H15: +≈14 млн
A16: 12 | B16: л.23–24 | C16: Перегородки | D16: Рейки ЛДСП 40×80 — «27 шт» на каждом листе | E16: 27 + 27 | F16: ✎ | G16: 27 реек = одна панель 1860 (27×40 + 26×30). По л.2 в каждой зоне ДВА проёма по 1860 → 54 + 54 | H16: +≈9,7 млн
... A22: 18 | B22: — | C22: Столешницы | D22: Столешницы для М6, М10, М14, тумбы, ниш поддонов | E22: отсутствует | F22: ⚠ | G22: Не специфицированы. В цене кухни (МБ-КУХ-ПМ) заложена ЛДСП; камень +≈2 млн/п.м. | H22: —

Sheet Фитнес
A1: Фитнес — -1 этаж (139,58 м², РП Insydrium, 29 л.)
A2: Кол-во и «Цена ручн.» — синие вводные. Цена берётся из листа «Прайс» по коду, ручная цена перекрывает прайс. Жёлтые «?» — данных нет, сумма по строке = 0 до заполнения. Оранжевые — количество предположено, проверить по РП.
A4: № | B4: Раздел | C4: Наименование | D4: Характеристика | E4: Ед. | F4: Кол-во | G4: Код прайса | H4: Цена ручн. | I4: Цена | J4: Сумма | K4: Откуда кол-во | L4: Примечание
A5: 1 | B5: Освещение | C5: L-1 Магнитный трек 3000 мм, подвес 450 мм | E5: шт | F5: 23 | G5: ОС-РЕЛЬС-3 | I5: =IF(ISNUMBER(H5),H5,IF(G5<>"",IFERROR(INDEX(Прайс!$G$5:$G$150,MATCH(G5,Прайс!$A$5:$A$150,0)),""),"")) -> 250000 | J5: =IF(AND(ISNUMBER(F5),ISNUMBER(I5)),F5*I5,"") -> 5750000 | K5: по РП
A6: 2 | B6: Освещение | C6: L-2 Магнитный трек 2000 мм, подвес 450 мм | E6: шт | F6: 12 | G6: ОС-РЕЛЬС-2 | I6: =IF(ISNUMBER(H6),H6,IF(G6<>"",IFERROR(INDEX(Прайс!$G$5:$G$150,MATCH(G6,Прайс!$A$5:$A$150,0)),""),"")) -> 170000 | J6: =IF(AND(ISNUMBER(F6),ISNUMBER(I6)),F6*I6,"") -> 2040000 | K6: по РП | L6: всего 93 п.м. трека
A7: 3 | B7: Освещение | C7: L-3 Поворотный спот | D7: 24 Вт | E7: шт | F7: 128 | G7: ОС-СПОТ-МАГ | I7: =IF(ISNUMBER(H7),H7,IF(G7<>"",IFERROR(INDEX(Прайс!$G$5:$G$150,MATCH(G7,Прайс!$A$5:$A$150,0)),""),"")) -> 100000 | J7: =IF(AND(ISNUMBER(F7),ISNUMBER(I7)),F7*I7,"") -> 12800000 | K7: по РП | L7: 3,07 кВт суммарно; CRI ≥ 90 проверить на образце
A8: 4 | B8: Освещение | C8: L-4 Точечный светильник | E8: шт | F8: 9 | G8: ОС-ТОЧ | I8: =IF(ISNUMBER(H8),H8,IF(G8<>"",IFERROR(INDEX(Прайс!$G$5:$G$150,MATCH(G8,Прайс!$A$5:$A$150,0)),""),"")) -> 150000 | J8: =IF(AND(ISNUMBER(F8),ISNUMBER(I8)),F8*I8,"") -> 1350000 | K8: по РП
A9: 5 | B9: Освещение | C9: L-5 Бра 900 мм | E9: шт | F9: 2 | G9: ОС-БРА-90 | I9: =IF(ISNUMBER(H9),H9,IF(G9<>"",IFERROR(INDEX(Прайс!$G$5:$G$150,MATCH(G9,Прайс!$A$5:$A$150,0)),""),"")) -> 300000 | J9: =IF(AND(ISNUMBER(F9),ISNUMBER(I9)),F9*I9,"") -> 600000 | K9: по РП
A10: 6 | B10: Освещение | C10: Тросы подвеса | D10: 3 шт на 3 м, 2 шт на 2 м | E10: шт | F10: 93 | G10: ОС-ТРОС | I10: =IF(ISNUMBER(H10),H10,IF(G10<>"",IFERROR(INDEX(Прайс!$G$5:$G$150,MATCH(G10,Прайс!$A$5:$A$150,0)),""),"")) -> 35000 | J10: =IF(AND(ISNUMBER(F10),ISNUMBER(I10)),F10*I10,"") -> 3255000 | K10: предп. (расчёт) | L10: в РП нет
A11: 7 | B11: Освещение | C11: Блок питания 48V 400 Вт | D11: 3,07 кВт / 320 Вт полезных | E11: шт | F11: 10 | G11: ОС-БП-400 | I11: =IF(ISNUMBER(H11),H11,IF(G11<>"",IFERROR(INDEX(Прайс!$G$5:$G$150,MATCH(G11,Прайс!$A$5:$A$150,0)),""),"")) -> 200000 | J11: =IF(AND(ISNUMBER(F11),ISNUMBER(I11)),F11*I11,"") -> 2000000 | K11: предп. (расчёт) | L11: в РП нет
A12: 8 | B12: Освещение | C12: Соединители рельсов | D12: 35 отрезков | E12: шт | F12: 35 | G12: ОС-СОЕД | I12: =IF(ISNUMBER(H12),H12,IF(G12<>"",IFERROR(INDEX(Прайс!$G$5:$G$150,MATCH(G12,Прайс!$A$5:$A$150,0)),""),"")) -> 25000 | J12: =IF(AND(ISNUMBER(F12),ISNUMBER(I12)),F12*I12,"") -> 875000 | K12: предп. (расчёт) | L12: в РП нет
A13: 9 | B13: Сантехника | C13: Душевая кабина / ограждение | D13: душевые 1,78 и 1,75 м² | E13: шт | F13: 2 | G13: СН-ДУШКАБ | I13: =IF(ISNUMBER(H13),H13,IF(G13<>"",IFERROR(INDEX(Прайс!$G$5:$G$150,MATCH(G13,Прайс!$A$5:$A$150,0)),""),"")) -> 3500000 | J13: =IF(AND(ISNUMBER(F13),ISNUMBER(I13)),F13*I13,"") -> 7000000 | K13: по РП
A14: 10 | B14: Сантехника | C14: Смеситель душевой | E14: шт | F14: 2 | G14: СН-СМ-ДУШ | I14: =IF(ISNUMBER(H14),H14,IF(G14<>"",IFERROR(INDEX(Прайс!$G$5:$G$150,MATCH(G14,Прайс!$A$5:$A$150,0)),""),"")) -> 1500000 | J14: =IF(AND(ISNUMBER(F14),ISNUMBER(I14)),F14*I14,"") -> 3000000 | K14: предп. | L14: в РП состав С-1…С-12 уточнить
A15: 11 | B15: Сантехника | C15: Трап душевой | E15: шт | F15: 2 | G15: СН-ТРАП | I15: =IF(ISNUMBER(H15),H15,IF(G15<>"",IFERROR(INDEX(Прайс!$G$5:$G$150,MATCH(G15,Прайс!$A$5:$A$150,0)),""),"")) -> 400000 | J15: =IF(AND(ISNUMBER(F15),ISNUMBER(I15)),F15*I15,"") -> 800000 | K15: предп.
A16: 12 | B16: Сантехника | C16: Раковина | D16: размер по РП уточнить | E16: шт | F16: 3 | G16: СН-РАК-500 | I16: =IF(ISNUMBER(H16),H16,IF(G16<>"",IFERROR(INDEX(Прайс!$G$5:$G$150,MATCH(G16,Прайс!$A$5:$A$150,0)),""),"")) -> 1100000 | J16: =IF(AND(ISNUMBER(F16),ISNUMBER(I16)),F16*I16,"") -> 3300000 | K16: по РП
A17: 13 | B17: Сантехника | C17: Смеситель для раковины | E17: шт | F17: 3 | G17: СН-СМ-НАКЛ | I17: =IF(ISNUMBER(H17),H17,IF(G17<>"",IFERROR(INDEX(Прайс!$G$5:$G$150,MATCH(G17,Прайс!$A$5:$A$150,0)),""),"")) -> 900000 | J17: =IF(AND(ISNUMBER(F17),ISNUMBER(I17)),F17*I17,"") -> 2700000 | K17: предп.
A18: 14 | B18: Сантехника | C18: Унитаз | D18: подвесной? | E18: шт | F18: 2 | G18: СН-УНИТ | I18: =IF(ISNUMBER(H18),H18,IF(G18<>"",IFERROR(INDEX(Прайс!$G$5:$G$150,MATCH(G18,Прайс!$A$5:$A$150,0)),""),"")) -> 2500000 | J18: =IF(AND(ISNUMBER(F18),ISNUMBER(I18)),F18*I18,"") -> 5000000 | K18: по РП | L18: тип уточнить
A19: 15 | B19: Сантехника | C19: Инсталляция | E19: шт | F19: 2 | G19: СН-ИНСТ | I19: =IF(ISNUMBER(H19),H19,IF(G19<>"",IFERROR(INDEX(Прайс!$G$5:$G$150,MATCH(G19,Прайс!$A$5:$A$150,0)),""),"")) -> 3000000 | J19: =IF(AND(ISNUMBER(F19),ISNUMBER(I19)),F19*I19,"") -> 6000000 | K19: предп. | L19: если подвесные
A20: 16 | B20: Сантехника | C20: Кнопка слива | E20: шт | F20: 2 | G20: СН-КНОП | I20: =IF(ISNUMBER(H20),H20,IF(G20<>"",IFERROR(INDEX(Прайс!$G$5:$G$150,MATCH(G20,Прайс!$A$5:$A$150,0)),""),"")) -> 700000 | J20: =IF(AND(ISNUMBER(F20),ISNUMBER(I20)),F20*I20,"") -> 1400000 | K20: предп.
A21: 17 | B21: Сантехника | C21: Зеркало в С/У | E21: шт | F21: 3 | G21: СН-ЗЕРК | I21: =IF(ISNUMBER(H21),H21,IF(G21<>"",IFERROR(INDEX(Прайс!$G$5:$G$150,MATCH(G21,Прайс!$A$5:$A$150,0)),""),"")) -> 600000 | J21: =IF(AND(ISNUMBER(F21),ISNUMBER(I21)),F21*I21,"") -> 1800000 | K21: по РП
A22: 18 | B22: Сантехника | C22: Канализационный насос для душа | D22: опция: сток из подвала | E22: шт | F22: 1 | G22: СН-НАСОС | I22: =IF(ISNUMBER(H22),H22,IF(G22<>"",IFERROR(INDEX(Прайс!$G$5:$G$150,MATCH(G22,Прайс!$A$5:$A$150,0)),""),"")) -> 4500000 | J22: =IF(AND(ISNUMBER(F22),ISNUMBER(I22)),F22*I22,"") -> 4500000 | K22: предп. (опция) | L22: решение не принято
A23: 19 | B23: Электрика | C23: Розетка (чёрная) | E23: шт | F23: 74 | G23: ЭЛ-РОЗ | I23: =IF(ISNUMBER(H23),H23,IF(G23<>"",IFERROR(INDEX(Прайс!$G$5:$G$150,MATCH(G23,Прайс!$A$5:$A$150,0)),""),"")) -> 65000 | J23: =IF(AND(ISNUMBER(F23),ISNUMBER(I23)),F23*I23,"") -> 4810000 | K23: предп. (аналог салона ×0.70) | L23: 105 в салоне на 200 м² → 139.58 м²; уточнить по РП
A24: 20 | B24: Электрика | C24: Выключатель 1-кл (чёрный) | E24: шт | F24: 6 | G24: ЭЛ-ВЫК1 | I24: =IF(ISNUMBER(H24),H24,IF(G24<>"",IFERROR(INDEX(Прайс!$G$5:$G$150,MATCH(G24,Прайс!$A$5:$A$150,0)),""),"")) -> 55000 | J24: =IF(AND(ISNUMBER(F24),ISNUMBER(I24)),F24*I24,"") -> 330000 | K24: предп. (аналог салона ×0.70) | L24: 8 в салоне на 200 м² → 139.58 м²; уточнить по РП
A25: 21 | B25: Электрика | C25: Выключатель 2-кл (чёрный) | E25: шт | F25: 21 | G25: ЭЛ-ВЫК2 | I25: =IF(ISNUMBER(H25),H25,IF(G25<>"",IFERROR(INDEX(Прайс!$G$5:$G$150,MATCH(G25,Прайс!$A$5:$A$150,0)),""),"")) -> 80000 | J25: =IF(AND(ISNUMBER(F25),ISNUMBER(I25)),F25*I25,"") -> 1680000 | K25: предп. (аналог салона ×0.70) | L25: 30 в салоне на 200 м² → 139.58 м²; уточнить по РП
A26: 22 | B26: Электрика | C26: Рамка 1-пост | E26: шт | F26: 7 | G26: ЭЛ-РАМ1 | I26: =IF(ISNUMBER(H26),H26,IF(G26<>"",IFERROR(INDEX(Прайс!$G$5:$G$150,MATCH(G26,Прайс!$A$5:$A$150,0)),""),"")) -> 25000 | J26: =IF(AND(ISNUMBER(F26),ISNUMBER(I26)),F26*I26,"") -> 175000 | K26: предп. (аналог салона ×0.70) | L26: 10 в салоне на 200 м² → 139.58 м²; уточнить по РП
A27: 23 | B27: Электрика | C27: Рамка 2-пост | E27: шт | F27: 8 | G27: ЭЛ-РАМ2 | I27: =IF(ISNUMBER(H27),H27,IF(G27<>"",IFERROR(INDEX(Прайс!$G$5:$G$150,MATCH(G27,Прайс!$A$5:$A$150,0)),""),"")) -> 45000 | J27: =IF(AND(ISNUMBER(F27),ISNUMBER(I27)),F27*I27,"") -> 360000 | K27: предп. (аналог салона ×0.70) | L27: 11 в салоне на 200 м² → 139.58 м²; уточнить по РП
A28: 24 | B28: Электрика | C28: Рамка 3-пост | E28: шт | F28: 6 | G28: ЭЛ-РАМ3 | I28: =IF(ISNUMBER(H28),H28,IF(G28<>"",IFERROR(INDEX(Прайс!$G$5:$G$150,MATCH(G28,Прайс!$A$5:$A$150,0)),""),"")) -> 65000 | J28: =IF(AND(ISNUMBER(F28),ISNUMBER(I28)),F28*I28,"") -> 390000 | K28: предп. (аналог салона ×0.70) | L28: 8 в салоне на 200 м² → 139.58 м²; уточнить по РП
A29: 25 | B29: Электрика | C29: Рамка 4-пост | E29: шт | F29: 9 | G29: ЭЛ-РАМ4 | I29: =IF(ISNUMBER(H29),H29,IF(G29<>"",IFERROR(INDEX(Прайс!$G$5:$G$150,MATCH(G29,Прайс!$A$5:$A$150,0)),""),"")) -> 85000 | J29: =IF(AND(ISNUMBER(F29),ISNUMBER(I29)),F29*I29,"") -> 765000 | K29: предп. (аналог салона ×0.70) | L29: 12 в салоне на 200 м² → 139.58 м²; уточнить по РП
A30: 26 | B30: Электрика | C30: Рамка 5-пост | E30: шт | F30: 3 | G30: ЭЛ-РАМ5 | I30: =IF(ISNUMBER(H30),H30,IF(G30<>"",IFERROR(INDEX(Прайс!$G$5:$G$150,MATCH(G30,Прайс!$A$5:$A$150,0)),""),"")) -> 105000 | J30: =IF(AND(ISNUMBER(F30),ISNUMBER(I30)),F30*I30,"") -> 315000 | K30: предп. (аналог салона ×0.70) | L30: 4 в салоне на 200 м² → 139.58 м²; уточнить по РП
A31: 27 | B31: Электрика | C31: Вывод UTP для камеры | E31: шт | F31: 7 | G31: ЭЛ-UTP | I31: =IF(ISNUMBER(H31),H31,IF(G31<>"",IFERROR(INDEX(Прайс!$G$5:$G$150,MATCH(G31,Прайс!$A$5:$A$150,0)),""),"")) -> 120000 | J31: =IF(AND(ISNUMBER(F31),ISNUMBER(I31)),F31*I31,"") -> 840000 | K31: предп. (аналог салона ×0.70) | L31: 9 в салоне на 200 м² → 139.58 м²; уточнить по РП
A32: 28 | B32: Электрика | C32: Вывод ТВ (питание + HDMI + UTP) | E32: шт | F32: 2 | G32: ЭЛ-ТВ | I32: =IF(ISNUMBER(H32),H32,IF(G32<>"",IFERROR(INDEX(Прайс!$G$5:$G$150,MATCH(G32,Прайс!$A$5:$A$150,0)),""),"")) -> 400000 | J32: =IF(AND(ISNUMBER(F32),ISNUMBER(I32)),F32*I32,"") -> 800000 | K32: предп. (аналог салона ×0.70) | L32: 2 в салоне на 200 м² → 139.58 м²; уточнить по РП
A33: 29 | B33: Тёплый пол | C33: Нагревательный мат IQ FLOOR MAT | D33: секции 4×1, 18×1 (санузлы/подсобки) | E33: м² | F33: 22 | G33: ТП-МАТ | I33: =IF(ISNUMBER(H33),H33,IF(G33<>"",IFERROR(INDEX(Прайс!$G$5:$G$150,MATCH(G33,Прайс!$A$5:$A$150,0)),""),"")) -> 419070 | J33: =IF(AND(ISNUMBER(F33),ISNUMBER(I33)),F33*I33,"") -> 9219540 | K33: по подбору (stab.uz)
A34: 30 | B34: Тёплый пол | C34: Терморегулятор | E34: шт | F34: 2 | G34: ЭЛ-ТЕРМ | I34: =IF(ISNUMBER(H34),H34,IF(G34<>"",IFERROR(INDEX(Прайс!$G$5:$G$150,MATCH(G34,Прайс!$A$5:$A$150,0)),""),"")) -> 350000 | J34: =IF(AND(ISNUMBER(F34),ISNUMBER(I34)),F34*I34,"") -> 700000 | K34: предп. (по секциям)
A35: 31 | B35: Полы | C35: НП-2 Резиновое покрытие | D35: тренажёрный зал | E35: м² | F35: 59.06 | G35: ПЛ-РЕЗИНА | I35: =IF(ISNUMBER(H35),H35,IF(G35<>"",IFERROR(INDEX(Прайс!$G$5:$G$150,MATCH(G35,Прайс!$A$5:$A$150,0)),""),"")) -> 350000 | J35: =IF(AND(ISNUMBER(F35),ISNUMBER(I35)),F35*I35,"") -> 20671000 | K35: по РП
A36: 32 | B36: Полы | C36: НП-1 Перекрытие (покрытие не определено) | E36: м² | F36: 73.64 | I36: =IF(ISNUMBER(H36),H36,IF(G36<>"",IFERROR(INDEX(Прайс!$G$5:$G$150,MATCH(G36,Прайс!$A$5:$A$150,0)),""),"")) | J36: =IF(AND(ISNUMBER(F36),ISNUMBER(I36)),F36*I36,"") | K36: по РП | L36: финишное покрытие уточнить — цена не задана
A37: 33 | B37: Стены / потолок | C37: Покраска стен От- | E37: м² | F37: 81.8 | G37: СТ-КРАСКА-СТ | I37: =IF(ISNUMBER(H37),H37,IF(G37<>"",IFERROR(INDEX(Прайс!$G$5:$G$150,MATCH(G37,Прайс!$A$5:$A$150,0)),""),"")) -> 32000 | J37: =IF(AND(ISNUMBER(F37),ISNUMBER(I37)),F37*I37,"") -> 2617600 | K37: по РП
A38: 34 | B38: Стены / потолок | C38: Окраска потолка чёрная | E38: м² | F38: 125.3 | G38: СТ-КРАСКА-ПОТ | I38: =IF(ISNUMBER(H38),H38,IF(G38<>"",IFERROR(INDEX(Прайс!$G$5:$G$150,MATCH(G38,Прайс!$A$5:$A$150,0)),""),"")) -> 25000 | J38: =IF(AND(ISNUMBER(F38),ISNUMBER(I38)),F38*I38,"") -> 3132500 | K38: по РП | L38: чёрная краска — цена может быть выше
A39: 35 | B39: Стены / потолок | C39: Плитка настенная От- | E39: м² | F39: 49.8 | G39: СТ-ПЛИТКА | I39: =IF(ISNUMBER(H39),H39,IF(G39<>"",IFERROR(INDEX(Прайс!$G$5:$G$150,MATCH(G39,Прайс!$A$5:$A$150,0)),""),"")) -> 250000 | J39: =IF(AND(ISNUMBER(F39),ISNUMBER(I39)),F39*I39,"") -> 12450000 | K39: по РП
A40: 36 | B40: Стены / потолок | C40: Зеркала настенные От- | E40: м² | F40: 40.2 | G40: СТ-ЗЕРКАЛО | I40: =IF(ISNUMBER(H40),H40,IF(G40<>"",IFERROR(INDEX(Прайс!$G$5:$G$150,MATCH(G40,Прайс!$A$5:$A$150,0)),""),"")) -> 400000 | J40: =IF(AND(ISNUMBER(F40),ISNUMBER(I40)),F40*I40,"") -> 16080000 | K40: по РП
A41: 37 | B41: Стены / потолок | C41: Сетка От- | E41: м² | F41: 53.9 | G41: СТ-СЕТКА | I41: =IF(ISNUMBER(H41),H41,IF(G41<>"",IFERROR(INDEX(Прайс!$G$5:$G$150,MATCH(G41,Прайс!$A$5:$A$150,0)),""),"")) -> 150000 | J41: =IF(AND(ISNUMBER(F41),ISNUMBER(I41)),F41*I41,"") -> 8085000 | K41: по РП | L41: что за сетка — уточнить по РП
...

Sheet Офис
A1: Офис — 3 этаж (185,66 м², РП insidroom «Office Navoi»)
A2: Кол-во и «Цена ручн.» — синие вводные. Цена берётся из листа «Прайс» по коду, ручная цена перекрывает прайс. Жёлтые «?» — данных нет, сумма по строке = 0 до заполнения. Оранжевые — количество предположено, проверить по РП.
A4: № | B4: Раздел | C4: Наименование | D4: Характеристика | E4: Ед. | F4: Кол-во | G4: Код прайса | H4: Цена ручн. | I4: Цена | J4: Сумма | K4: Откуда кол-во | L4: Примечание
A5: 1 | B5: Остекление | C5: Офис. Стеклянные перегородки: стекло 10 мм прозрачное закалённое с пескоструйной обработкой | D5: 77 м² перегородок + 5 распашных дверей 800–900 | E5: компл | F5: 1 | H5: 40500000 | I5: =IF(ISNUMBER(H5),H5,IF(G5<>"",IFERROR(INDEX(Прайс!$G$5:$G$150,MATCH(G5,Прайс!$A$5:$A$150,0)),""),"")) -> 40500000 | J5: =IF(AND(ISNUMBER(F5),ISNUMBER(I5)),F5*I5,"") -> 40500000 | K5: КП Imzo (вариант 2) | L5: выбранный вариант 2
A6: 2 | B6: Полы | C6: НП1 Керамогранит 1200×600 | E6: м² | F6: 11.1 | G6: ПЛ-КГ1200x600 | I6: =IF(ISNUMBER(H6),H6,IF(G6<>"",IFERROR(INDEX(Прайс!$G$5:$G$150,MATCH(G6,Прайс!$A$5:$A$150,0)),""),"")) -> 350000 | J6: =IF(AND(ISNUMBER(F6),ISNUMBER(I6)),F6*I6,"") -> 3885000 | K6: по РП
A7: 3 | B7: Полы | C7: НП3 Керамогранит 600×600 | E7: м² | F7: 36.69 | G7: ПЛ-КГ600 | I7: =IF(ISNUMBER(H7),H7,IF(G7<>"",IFERROR(INDEX(Прайс!$G$5:$G$150,MATCH(G7,Прайс!$A$5:$A$150,0)),""),"")) -> 220000 | J7: =IF(AND(ISNUMBER(F7),ISNUMBER(I7)),F7*I7,"") -> 8071800 | K7: по РП
A8: 4 | B8: Полы | C8: НП2 покрытие вместо линолеума (под тёплый пол) | E8: м² | F8: 130.07 | I8: =IF(ISNUMBER(H8),H8,IF(G8<>"",IFERROR(INDEX(Прайс!$G$5:$G$150,MATCH(G8,Прайс!$A$5:$A$150,0)),""),"")) | J8: =IF(AND(ISNUMBER(F8),ISNUMBER(I8)),F8*I8,"") | K8: по РП (переопределить) | L8: линолеум отменён — покрытие и цена не выбраны
A9: 5 | B9: Тёплый пол | C9: Нагревательный мат IQ FLOOR MAT | D9: секции 20×5, 18, 16, 5 | E9: м² | F9: 139 | G9: ТП-МАТ | I9: =IF(ISNUMBER(H9),H9,IF(G9<>"",IFERROR(INDEX(Прайс!$G$5:$G$150,MATCH(G9,Прайс!$A$5:$A$150,0)),""),"")) -> 419070 | J9: =IF(AND(ISNUMBER(F9),ISNUMBER(I9)),F9*I9,"") -> 58250730 | K9: по подбору (stab.uz)
A10: 6 | B10: Тёплый пол | C10: Терморегулятор | E10: шт | F10: 8 | G10: ЭЛ-ТЕРМ | I10: =IF(ISNUMBER(H10),H10,IF(G10<>"",IFERROR(INDEX(Прайс!$G$5:$G$150,MATCH(G10,Прайс!$A$5:$A$150,0)),""),"")) -> 350000 | J10: =IF(AND(ISNUMBER(F10),ISNUMBER(I10)),F10*I10,"") -> 2800000 | K10: предп. (по секциям) | L10: в РП есть только обозначение термостата
A11: 7 | B11: Сантехника | C11: Унитаз подвесной | E11: шт | F11: 1 | G11: СН-УНИТ | I11: =IF(ISNUMBER(H11),H11,IF(G11<>"",IFERROR(INDEX(Прайс!$G$5:$G$150,MATCH(G11,Прайс!$A$5:$A$150,0)),""),"")) -> 2500000 | J11: =IF(AND(ISNUMBER(F11),ISNUMBER(I11)),F11*I11,"") -> 2500000 | K11: предп. (аналог салона) | L11: 1 С/У; уточнить по РП
A12: 8 | B12: Сантехника | C12: Инсталляция для унитаза | E12: шт | F12: 1 | G12: СН-ИНСТ | I12: =IF(ISNUMBER(H12),H12,IF(G12<>"",IFERROR(INDEX(Прайс!$G$5:$G$150,MATCH(G12,Прайс!$A$5:$A$150,0)),""),"")) -> 3000000 | J12: =IF(AND(ISNUMBER(F12),ISNUMBER(I12)),F12*I12,"") -> 3000000 | K12: предп. (аналог салона)
A13: 9 | B13: Сантехника | C13: Кнопка слива | E13: шт | F13: 1 | G13: СН-КНОП | I13: =IF(ISNUMBER(H13),H13,IF(G13<>"",IFERROR(INDEX(Прайс!$G$5:$G$150,MATCH(G13,Прайс!$A$5:$A$150,0)),""),"")) -> 700000 | J13: =IF(AND(ISNUMBER(F13),ISNUMBER(I13)),F13*I13,"") -> 700000 | K13: предп. (аналог салона)
A14: 10 | B14: Сантехника | C14: Гигиенический душ | E14: шт | F14: 1 | G14: СН-ГИГДУШ | I14: =IF(ISNUMBER(H14),H14,IF(G14<>"",IFERROR(INDEX(Прайс!$G$5:$G$150,MATCH(G14,Прайс!$A$5:$A$150,0)),""),"")) -> 900000 | J14: =IF(AND(ISNUMBER(F14),ISNUMBER(I14)),F14*I14,"") -> 900000 | K14: предп. (аналог салона)
A15: 11 | B15: Сантехника | C15: Раковина накладная 600×400 | D15: С/У | E15: шт | F15: 1 | G15: СН-РАК-600 | I15: =IF(ISNUMBER(H15),H15,IF(G15<>"",IFERROR(INDEX(Прайс!$G$5:$G$150,MATCH(G15,Прайс!$A$5:$A$150,0)),""),"")) -> 1300000 | J15: =IF(AND(ISNUMBER(F15),ISNUMBER(I15)),F15*I15,"") -> 1300000 | K15: предп. (аналог салона)
A16: 12 | B16: Сантехника | C16: Смеситель для раковины | E16: шт | F16: 1 | G16: СН-СМ-НАКЛ | I16: =IF(ISNUMBER(H16),H16,IF(G16<>"",IFERROR(INDEX(Прайс!$G$5:$G$150,MATCH(G16,Прайс!$A$5:$A$150,0)),""),"")) -> 900000 | J16: =IF(AND(ISNUMBER(F16),ISNUMBER(I16)),F16*I16,"") -> 900000 | K16: предп. (аналог салона)
A17: 13 | B17: Сантехника | C17: Мойка кухонная 450×450 | D17: мини-кухня | E17: шт | F17: 1 | G17: СН-РАК-КУХ-М | I17: =IF(ISNUMBER(H17),H17,IF(G17<>"",IFERROR(INDEX(Прайс!$G$5:$G$150,MATCH(G17,Прайс!$A$5:$A$150,0)),""),"")) -> 900000 | J17: =IF(AND(ISNUMBER(F17),ISNUMBER(I17)),F17*I17,"") -> 900000 | K17: предп. (аналог салона) | L17: если в офисе есть кухня
A18: 14 | B18: Сантехника | C18: Смеситель кухонный | E18: шт | F18: 1 | G18: СН-СМ-КУХ | I18: =IF(ISNUMBER(H18),H18,IF(G18<>"",IFERROR(INDEX(Прайс!$G$5:$G$150,MATCH(G18,Прайс!$A$5:$A$150,0)),""),"")) -> 1200000 | J18: =IF(AND(ISNUMBER(F18),ISNUMBER(I18)),F18*I18,"") -> 1200000 | K18: предп. (аналог салона)
A19: 15 | B19: Электрика | C19: Розетка (чёрная) | E19: шт | F19: 98 | G19: ЭЛ-РОЗ | I19: =IF(ISNUMBER(H19),H19,IF(G19<>"",IFERROR(INDEX(Прайс!$G$5:$G$150,MATCH(G19,Прайс!$A$5:$A$150,0)),""),"")) -> 65000 | J19: =IF(AND(ISNUMBER(F19),ISNUMBER(I19)),F19*I19,"") -> 6370000 | K19: предп. (аналог салона ×0.93) | L19: 105 в салоне на 200 м² → 185.66 м²; уточнить по РП
A20: 16 | B20: Электрика | C20: Выключатель 1-кл (чёрный) | E20: шт | F20: 8 | G20: ЭЛ-ВЫК1 | I20: =IF(ISNUMBER(H20),H20,IF(G20<>"",IFERROR(INDEX(Прайс!$G$5:$G$150,MATCH(G20,Прайс!$A$5:$A$150,0)),""),"")) -> 55000 | J20: =IF(AND(ISNUMBER(F20),ISNUMBER(I20)),F20*I20,"") -> 440000 | K20: предп. (аналог салона ×0.93) | L20: 8 в салоне на 200 м² → 185.66 м²; уточнить по РП
A21: 17 | B21: Электрика | C21: Выключатель 2-кл (чёрный) | E21: шт | F21: 28 | G21: ЭЛ-ВЫК2 | I21: =IF(ISNUMBER(H21),H21,IF(G21<>"",IFERROR(INDEX(Прайс!$G$5:$G$150,MATCH(G21,Прайс!$A$5:$A$150,0)),""),"")) -> 80000 | J21: =IF(AND(ISNUMBER(F21),ISNUMBER(I21)),F21*I21,"") -> 2240000 | K21: предп. (аналог салона ×0.93) | L21: 30 в салоне на 200 м² → 185.66 м²; уточнить по РП
A22: 18 | B22: Электрика | C22: Рамка 1-пост | E22: шт | F22: 10 | G22: ЭЛ-РАМ1 | I22: =IF(ISNUMBER(H22),H22,IF(G22<>"",IFERROR(INDEX(Прайс!$G$5:$G$150,MATCH(G22,Прайс!$A$5:$A$150,0)),""),"")) -> 25000 | J22: =IF(AND(ISNUMBER(F22),ISNUMBER(I22)),F22*I22,"") -> 250000 | K22: предп. (аналог салона ×0.93) | L22: 10 в салоне на 200 м² → 185.66 м²; уточнить по РП
A23: 19 | B23: Электрика | C23: Рамка 2-пост | E23: шт | F23: 11 | G23: ЭЛ-РАМ2 | I23: =IF(ISNUMBER(H23),H23,IF(G23<>"",IFERROR(INDEX(Прайс!$G$5:$G$150,MATCH(G23,Прайс!$A$5:$A$150,0)),""),"")) -> 45000 | J23: =IF(AND(ISNUMBER(F23),ISNUMBER(I23)),F23*I23,"") -> 495000 | K23: предп. (аналог салона ×0.93) | L23: 11 в салоне на 200 м² → 185.66 м²; уточнить по РП
A24: 20 | B24: Электрика | C24: Рамка 3-пост | E24: шт | F24: 8 | G24: ЭЛ-РАМ3 | I24: =IF(ISNUMBER(H24),H24,IF(G24<>"",IFERROR(INDEX(Прайс!$G$5:$G$150,MATCH(G24,Прайс!$A$5:$A$150,0)),""),"")) -> 65000 | J24: =IF(AND(ISNUMBER(F24),ISNUMBER(I24)),F24*I24,"") -> 520000 | K24: предп. (аналог салона ×0.93) | L24: 8 в салоне на 200 м² → 185.66 м²; уточнить по РП
A25: 21 | B25: Электрика | C25: Рамка 4-пост | E25: шт | F25: 12 | G25: ЭЛ-РАМ4 | I25: =IF(ISNUMBER(H25),H25,IF(G25<>"",IFERROR(INDEX(Прайс!$G$5:$G$150,MATCH(G25,Прайс!$A$5:$A$150,0)),""),"")) -> 85000 | J25: =IF(AND(ISNUMBER(F25),ISNUMBER(I25)),F25*I25,"") -> 1020000 | K25: предп. (аналог салона ×0.93) | L25: 12 в салоне на 200 м² → 185.66 м²; уточнить по РП
A26: 22 | B26: Электрика | C26: Рамка 5-пост | E26: шт | F26: 4 | G26: ЭЛ-РАМ5 | I26: =IF(ISNUMBER(H26),H26,IF(G26<>"",IFERROR(INDEX(Прайс!$G$5:$G$150,MATCH(G26,Прайс!$A$5:$A$150,0)),""),"")) -> 105000 | J26: =IF(AND(ISNUMBER(F26),ISNUMBER(I26)),F26*I26,"") -> 420000 | K26: предп. (аналог салона ×0.93) | L26: 4 в салоне на 200 м² → 185.66 м²; уточнить по РП
A27: 23 | B27: Электрика | C27: Вывод UTP для камеры | E27: шт | F27: 9 | G27: ЭЛ-UTP | I27: =IF(ISNUMBER(H27),H27,IF(G27<>"",IFERROR(INDEX(Прайс!$G$5:$G$150,MATCH(G27,Прайс!$A$5:$A$150,0)),""),"")) -> 120000 | J27: =IF(AND(ISNUMBER(F27),ISNUMBER(I27)),F27*I27,"") -> 1080000 | K27: предп. (аналог салона ×0.93) | L27: 9 в салоне на 200 м² → 185.66 м²; уточнить по РП
A28: 24 | B28: Электрика | C28: Вывод ТВ (питание + HDMI + UTP) | E28: шт | F28: 2 | G28: ЭЛ-ТВ | I28: =IF(ISNUMBER(H28),H28,IF(G28<>"",IFERROR(INDEX(Прайс!$G$5:$G$150,MATCH(G28,Прайс!$A$5:$A$150,0)),""),"")) -> 400000 | J28: =IF(AND(ISNUMBER(F28),ISNUMBER(I28)),F28*I28,"") -> 800000 | K28: предп. (аналог салона ×0.93) | L28: 2 в салоне на 200 м² → 185.66 м²; уточнить по РП
A29: 25 | B29: Освещение | C29: Спот магнитный поворотный 24 Вт | E29: шт | F29: 94 | G29: ОС-СПОТ-МАГ | I29: =IF(ISNUMBER(H29),H29,IF(G29<>"",IFERROR(INDEX(Прайс!$G$5:$G$150,MATCH(G29,Прайс!$A$5:$A$150,0)),""),"")) -> 100000 | J29: =IF(AND(ISNUMBER(F29),ISNUMBER(I29)),F29*I29,"") -> 9400000 | K29: предп. (аналог салона ×0.93) | L29: 101 в салоне на 200 м² → 185.66 м²; уточнить по РП
A30: 26 | B30: Освещение | C30: Магнитный шинопровод подвесной | E30: п.м. | F30: 61 | G30: ОС-РЕЛЬС-М | I30: =IF(ISNUMBER(H30),H30,IF(G30<>"",IFERROR(INDEX(Прайс!$G$5:$G$150,MATCH(G30,Прайс!$A$5:$A$150,0)),""),"")) -> 85000 | J30: =IF(AND(ISNUMBER(F30),ISNUMBER(I30)),F30*I30,"") -> 5185000 | K30: предп. (аналог салона ×0.93) | L30: 66 в салоне на 200 м² → 185.66 м²; уточнить по РП
... A33: 29 | B33: Освещение | C33: Соединители рельсов | E33: шт | F33: 19 | G33: ОС-СОЕД-МЕТ | I33: =IF(ISNUMBER(H33),H33,IF(G33<>"",IFERROR(INDEX(Прайс!$G$5:$G$150,MATCH(G33,Прайс!$A$5:$A$150,0)),""),"")) -> 40000 | J33: =IF(AND(ISNUMBER(F33),ISNUMBER(I33)),F33*I33,"") -> 760000 | K33: предп. (аналог салона ×0.93) | L33: 20 в салоне на 200 м² → 185.66 м²; уточнить по РП
A34: 30 | B34: LED-подсветка | C34: Теневой плинтус с LED | D34: зависит от дизайна — под вопросом | E34: п.м. | F34: 95 | G34: LED-ПЛИНТ | I34: =IF(ISNUMBER(H34),H34,IF(G34<>"",IFERROR(INDEX(Прайс!$G$5:$G$150,MATCH(G34,Прайс!$A$5:$A$150,0)),""),"")) -> 220000 | J34: =IF(AND(ISNUMBER(F34),ISNUMBER(I34)),F34*I34,"") -> 20900000 | K34: предп. (аналог салона ×0.93) | L34: 102 в салоне на 200 м² → 185.66 м²; уточнить по РП
A35: 31 | B35: Стены / потолок | C35: Краска для потолка | D35: с запасом +15 % | E35: м² | F35: 269 | G35: СТ-КРАСКА-ПОТ | I35: =IF(ISNUMBER(H35),H35,IF(G35<>"",IFERROR(INDEX(Прайс!$G$5:$G$150,MATCH(G35,Прайс!$A$5:$A$150,0)),""),"")) -> 25000 | J35: =IF(AND(ISNUMBER(F35),ISNUMBER(I35)),F35*I35,"") -> 6725000 | K35: предп. (аналог салона ×0.93) | L35: 290 в салоне на 200 м² → 185.66 м²; уточнить по РП
A36: 32 | B36: Стены / потолок | C36: Краска для стен | D36: с запасом +15 % | E36: м² | F36: 325 | G36: СТ-КРАСКА-СТ | I36: =IF(ISNUMBER(H36),H36,IF(G36<>"",IFERROR(INDEX(Прайс!$G$5:$G$150,MATCH(G36,Прайс!$A$5:$A$150,0)),""),"")) -> 32000 | J36: =IF(AND(ISNUMBER(F36),ISNUMBER(I36)),F36*I36,"") -> 10400000 | K36: предп. (аналог салона ×0.93) | L36: 350 в салоне на 200 м² → 185.66 м²; уточнить по РП
I37: ИТОГО | J37: =SUM(J5:J36) -> 195157530
I38: строк без цены | J38: =COUNTBLANK(I5:I36) -> 1
I39: строк с «?» | J39: =COUNTIF(F5:F36,"~?") -> 0

Sheet Терраса
A1: Терраса — «РП Navoi Terrace» (227,5 м² обмер / 209,87 м² проект)
A2: Кол-во и «Цена ручн.» — синие вводные. Цена берётся из листа «Прайс» по коду, ручная цена перекрывает прайс. Жёлтые «?» — данных нет, сумма по строке = 0 до заполнения. Оранжевые — количество предположено, проверить по РП.
A4: № | B4: Раздел | C4: Наименование | D4: Характеристика | E4: Ед. | F4: Кол-во | G4: Код прайса | H4: Цена ручн. | I4: Цена | J4: Сумма | K4: Откуда кол-во | L4: Примечание
A5: 1 | B5: Остекление | C5: Терраса. Раздвижная система остекления Imzo: алюминиевый профиль, раздвижные створки, щёточный уплотнитель («шотландка») 18 мм. Комплект с фурнитурой | D5: 83 м² + раздвижная дверь | E5: компл | F5: 1 | H5: 128000000 | I5: =IF(ISNUMBER(H5),H5,IF(G5<>"",IFERROR(INDEX(Прайс!$G$5:$G$150,MATCH(G5,Прайс!$A$5:$A$150,0)),""),"")) -> 128000000 | J5: =IF(AND(ISNUMBER(F5),ISNUMBER(I5)),F5*I5,"") -> 128000000 | K5: КП Imzo (вариант 2) | L5: выбранный вариант 2
A6: 2 | B6: Остекление | C6: Фасад. Фасадное (витражное) остекление здания | D6: 227 м²; +1 500 000 за каждое открывание | E6: компл | F6: 1 | H6: 156000000 | I6: =IF(ISNUMBER(H6),H6,IF(G6<>"",IFERROR(INDEX(Прайс!$G$5:$G$150,MATCH(G6,Прайс!$A$5:$A$150,0)),""),"")) -> 156000000 | J6: =IF(AND(ISNUMBER(F6),ISNUMBER(I6)),F6*I6,"") -> 156000000 | K6: КП Imzo (вариант 2) | L6: по зданию, отнесено к террасе условно
A7: 3 | B7: Тёплый пол | C7: Нагревательный мат IQ FLOOR MAT | D7: в пределах 50 м² | E7: м² | F7: 50 | G7: ТП-МАТ | I7: =IF(ISNUMBER(H7),H7,IF(G7<>"",IFERROR(INDEX(Прайс!$G$5:$G$150,MATCH(G7,Прайс!$A$5:$A$150,0)),""),"")) -> 419070 | J7: =IF(AND(ISNUMBER(F7),ISNUMBER(I7)),F7*I7,"") -> 20953500 | K7: по решению Тимура | L7: секции подобрать
A8: 4 | B8: Тёплый пол | C8: Терморегулятор | D8: ~3 секции по 20 м² | E8: шт | F8: 3 | G8: ЭЛ-ТЕРМ | I8: =IF(ISNUMBER(H8),H8,IF(G8<>"",IFERROR(INDEX(Прайс!$G$5:$G$150,MATCH(G8,Прайс!$A$5:$A$150,0)),""),"")) -> 350000 | J8: =IF(AND(ISNUMBER(F8),ISNUMBER(I8)),F8*I8,"") -> 1050000 | K8: предп. (по секциям)
A9: 5 | B9: Сантехника | C9: Унитаз подвесной | D9: санузел 4,14 м² | E9: шт | F9: 1 | G9: СН-УНИТ | I9: =IF(ISNUMBER(H9),H9,IF(G9<>"",IFERROR(INDEX(Прайс!$G$5:$G$150,MATCH(G9,Прайс!$A$5:$A$150,0)),""),"")) -> 2500000 | J9: =IF(AND(ISNUMBER(F9),ISNUMBER(I9)),F9*I9,"") -> 2500000 | K9: предп. (аналог салона) | L9: уточнить по РП
